<?xml version="1.0" encoding="utf-8"?>
<!-- This URDF was automatically created by SolidWorks to URDF Exporter! Originally created by Stephen Brawner (brawner@gmail.com) 
     Commit Version: 1.6.0-4-g7f85cfe  Build Version: 1.6.7995.38578
     For more information, please see http://wiki.ros.org/sw_urdf_exporter -->
<robot
  name="UR5_simplified">
  <link
    name="base_link">
    <inertial>
      <origin
        xyz="-0.000420030422995675 0.0163366044723407 0.000420045041829593"
        rpy="0 0 0" />
      <mass
        value="0.44130548858899" />
      <inertia
        ixx="0.000536733963070829"
        ixy="1.52397192563187E-06"
        ixz="-1.75291479004569E-05"
        iyy="0.000965019557497327"
        iyz="-1.52398754952585E-06"
        izz="0.000536733421587594" />
    </inertial>
    <visual>
      <origin
        xyz="0 0 0"
        rpy="0 0 0" />
      <geometry>
        <mesh
          filename="package://UR5_simplified/meshes/base_link.STL" />
      </geometry>
      <material
        name="">
        <color
          rgba="0.792156862745098 0.819607843137255 0.933333333333333 1" />
      </material>
    </visual>
    <collision>
      <origin
        xyz="0 0 0"
        rpy="0 0 0" />
      <geometry>
        <mesh
          filename="package://UR5_simplified/meshes/base_link.STL" />
      </geometry>
    </collision>
  </link>
  <link
    name="j1">
    <inertial>
      <origin
        xyz="-0.058879461765672 0.0151336322048917 -5.24202044640188E-06"
        rpy="0 0 0" />
      <mass
        value="1.51495048391269" />
      <inertia
        ixx="0.00282994613844968"
        ixy="0.000324668777850971"
        ixz="-1.47797176832201E-07"
        iyy="0.00247570172636265"
        iyz="3.82021832349878E-07"
        izz="0.00257580968014944" />
    </inertial>
    <visual>
      <origin
        xyz="0 0 0"
        rpy="0 0 0" />
      <geometry>
        <mesh
          filename="package://UR5_simplified/meshes/j1.STL" />
      </geometry>
      <material
        name="">
        <color
          rgba="0.792156862745098 0.819607843137255 0.933333333333333 1" />
      </material>
    </visual>
    <collision>
      <origin
        xyz="0 0 0"
        rpy="0 0 0" />
      <geometry>
        <mesh
          filename="package://UR5_simplified/meshes/j1.STL" />
      </geometry>
    </collision>
  </link>
  <joint
    name="j1"
    type="revolute">
    <origin
      xyz="0 0 0.0313"
      rpy="0 1.5708 0" />
    <parent
      link="base_link" />
    <child
      link="j1" />
    <axis
      xyz="1 0 0" />
    <limit
      lower="-4.7124"
      upper="0"
      effort="150"
      velocity="150" />
  </joint>
  <link
    name="j2">
    <inertial>
      <origin
        xyz="0.0648361658314044 -0.209004061376109 -1.23155221259878E-08"
        rpy="0 0 0" />
      <mass
        value="4.66729876573488" />
      <inertia
        ixx="0.0219294842247083"
        ixy="-7.18981949137377E-09"
        ixz="2.09104575114148E-09"
        iyy="0.00644094865252764"
        iyz="-7.57334074251366E-07"
        izz="0.0213552546161582" />
    </inertial>
    <visual>
      <origin
        xyz="0 0 0"
        rpy="0 0 0" />
      <geometry>
        <mesh
          filename="package://UR5_simplified/meshes/j2.STL" />
      </geometry>
      <material
        name="">
        <color
          rgba="0.792156862745098 0.819607843137255 0.933333333333333 1" />
      </material>
    </visual>
    <collision>
      <origin
        xyz="0 0 0"
        rpy="0 0 0" />
      <geometry>
        <mesh
          filename="package://UR5_simplified/meshes/j2.STL" />
      </geometry>
    </collision>
  </link>
  <joint
    name="j2"
    type="revolute">
    <origin
      xyz="-0.0597 0.075399 0"
      rpy="-3.1416 0 1.5708" />
    <parent
      link="j1" />
    <child
      link="j2" />
    <axis
      xyz="1 0 0" />
    <limit
      lower="0"
      upper="1.5708"
      effort="150"
      velocity="150" />
  </joint>
  <link
    name="j3">
    <inertial>
      <origin
        xyz="-0.173826493031852 -0.0474263574060036 -4.95434820006725E-08"
        rpy="0 0 0" />
      <mass
        value="2.39901324441344" />
      <inertia
        ixx="0.00204229586440966"
        ixy="-0.000125752505407837"
        ixz="-1.20659842072695E-08"
        iyy="0.0115872131206061"
        iyz="1.20783785634617E-08"
        izz="0.0114707961305417" />
    </inertial>
    <visual>
      <origin
        xyz="0 0 0"
        rpy="0 0 0" />
      <geometry>
        <mesh
          filename="package://UR5_simplified/meshes/j3.STL" />
      </geometry>
      <material
        name="">
        <color
          rgba="0.792156862745098 0.819607843137255 0.933333333333333 1" />
      </material>
    </visual>
    <collision>
      <origin
        xyz="0 0 0"
        rpy="0 0 0" />
      <geometry>
        <mesh
          filename="package://UR5_simplified/meshes/j3.STL" />
      </geometry>
    </collision>
  </link>
  <joint
    name="j3"
    type="revolute">
    <origin
      xyz="0 -0.425 0"
      rpy="3.1416 0 1.5708" />
    <parent
      link="j2" />
    <child
      link="j3" />
    <axis
      xyz="0 1 0" />
    <limit
      lower="-2.0944"
      upper="2.0944"
      effort="150"
      velocity="150" />
  </joint>
  <link
    name="j4">
    <inertial>
      <origin
        xyz="0.00644919885722728 0.0377917982433393 6.42638685486703E-09"
        rpy="0 0 0" />
      <mass
        value="0.321808563847766" />
      <inertia
        ixx="0.000268719586442726"
        ixy="-2.98851509149925E-05"
        ixz="-1.8842313869565E-10"
        iyy="0.000235433301847422"
        iyz="1.84465229647951E-10"
        izz="0.000253503684854722" />
    </inertial>
    <visual>
      <origin
        xyz="0 0 0"
        rpy="0 0 0" />
      <geometry>
        <mesh
          filename="package://UR5_simplified/meshes/j4.STL" />
      </geometry>
      <material
        name="">
        <color
          rgba="0.792156862745098 0.819607843137255 0.933333333333333 1" />
      </material>
    </visual>
    <collision>
      <origin
        xyz="0 0 0"
        rpy="0 0 0" />
      <geometry>
        <mesh
          filename="package://UR5_simplified/meshes/j4.STL" />
      </geometry>
    </collision>
  </link>
  <joint
    name="j4"
    type="revolute">
    <origin
      xyz="-0.40787 0.0076669 0"
      rpy="-3.1416 0 -3.1416" />
    <parent
      link="j3" />
    <child
      link="j4" />
    <axis
      xyz="0 1 0" />
    <limit
      lower="-3.1416"
      upper="0"
      effort="150"
      velocity="150" />
  </joint>
  <link
    name="j5">
    <inertial>
      <origin
        xyz="0.00644922475929381 0.0377917860992273 5.99930906098294E-09"
        rpy="0 0 0" />
      <mass
        value="0.321808531310946" />
      <inertia
        ixx="0.000268719642713045"
        ixy="-2.98851315554222E-05"
        ixz="2.77236661426714E-10"
        iyy="0.000235433171783743"
        iyz="-5.05263744647266E-11"
        izz="0.000253503506613561" />
    </inertial>
    <visual>
      <origin
        xyz="0 0 0"
        rpy="0 0 0" />
      <geometry>
        <mesh
          filename="package://UR5_simplified/meshes/j5.STL" />
      </geometry>
      <material
        name="">
        <color
          rgba="0.792156862745098 0.819607843137255 0.933333333333333 1" />
      </material>
    </visual>
    <collision>
      <origin
        xyz="0 0 0"
        rpy="0 0 0" />
      <geometry>
        <mesh
          filename="package://UR5_simplified/meshes/j5.STL" />
      </geometry>
    </collision>
  </link>
  <joint
    name="j5"
    type="revolute">
    <origin
      xyz="0.050217 0.045249 0"
      rpy="0 0 -1.5708" />
    <parent
      link="j4" />
    <child
      link="j5" />
    <axis
      xyz="0 1 0" />
    <limit
      lower="-4.7124"
      upper="0"
      effort="150"
      velocity="150" />
  </joint>
  <link
    name="j6">
    <inertial>
      <origin
        xyz="-1.15735176997589E-09 0.0218984674733232 0.000143128299193512"
        rpy="0 0 0" />
      <mass
        value="0.164823391159791" />
      <inertia
        ixx="6.80617682267473E-05"
        ixy="9.37822822097515E-13"
        ixz="-7.21007655945049E-11"
        iyy="0.000116042608880082"
        iyz="-1.05593403960908E-07"
        izz="6.87583432276169E-05" />
    </inertial>
    <visual>
      <origin
        xyz="0 0 0"
        rpy="0 0 0" />
      <geometry>
        <mesh
          filename="package://UR5_simplified/meshes/j6.STL" />
      </geometry>
      <material
        name="">
        <color
          rgba="0.792156862745098 0.819607843137255 0.933333333333333 1" />
      </material>
    </visual>
    <collision>
      <origin
        xyz="0 0 0"
        rpy="0 0 0" />
      <geometry>
        <mesh
          filename="package://UR5_simplified/meshes/j6.STL" />
      </geometry>
    </collision>
  </link>
  <joint
    name="j6"
    type="revolute">
    <origin
      xyz="0.064597 0.045249 0"
      rpy="0 0 -1.5708" />
    <parent
      link="j5" />
    <child
      link="j6" />
    <axis
      xyz="0 1 0" />
    <limit
      lower="-4.7124"
      upper="0"
      effort="150"
      velocity="150" />
  </joint>
  <link
    name="end_effector">
    <inertial>
      <origin
        xyz="2.66197477882812E-05 0.0228582541719834 -7.99360577730113E-15"
        rpy="0 0 0" />
      <mass
        value="0.0387244499068886" />
      <inertia
        ixx="7.6803939719158E-06"
        ixy="-6.30801942990225E-09"
        ixz="3.81314548483494E-21"
        iyy="1.4002426572648E-05"
        iyz="-7.93172946267574E-21"
        izz="7.70235609549383E-06" />
    </inertial>
    <visual>
      <origin
        xyz="0 0 0"
        rpy="0 0 0" />
      <geometry>
        <mesh
          filename="package://UR5_simplified/meshes/end_effector.STL" />
      </geometry>
      <material
        name="">
        <color
          rgba="0.752941176470588 0.752941176470588 0.752941176470588 1" />
      </material>
    </visual>
    <collision>
      <origin
        xyz="0 0 0"
        rpy="0 0 0" />
      <geometry>
        <mesh
          filename="package://UR5_simplified/meshes/end_effector.STL" />
      </geometry>
    </collision>
  </link>
  <joint
    name="end_effector"
    type="fixed">
    <origin
      xyz="0 0.077173 0"
      rpy="-3.1416 -0.7854 0" />
    <parent
      link="j6" />
    <child
      link="end_effector" />
    <axis
      xyz="0 0 0" />
  </joint>
</robot>